<?xml version="1.0" ?>
<sdf version="1.5">
  <model name="velodyne_hdl-32">
      <link name="base">
      <pose>-0.04267 -0.04267 0 0 0 -0.78535</pose>
        <inertial>
          <mass>0.1</mass>
          <inertia>
            <ixx>0.000090623</ixx>
            <iyy>0.000090623</iyy>
            <izz>0.000091036</izz>
            <ixy>0</ixy>
            <ixz>0</ixz>
            <iyz>0</iyz>
          </inertia>
        </inertial>
        <collision name="base_collision">
          <geometry>
            <sphere>
              <radius>0.04267</radius>
            </sphere>
          </geometry>
        </collision>

        <visual name="base_visual">
          <geometry>
            <sphere>
              <radius>0.04267</radius>
            </sphere>
          </geometry>
        </visual>
      </link>

      <link name="top">
      <pose>0 0 0.02133 0 0 0</pose>
        <inertial>
          <mass>0.0000000000001</mass>
          <inertia>
            <ixx>0.000090623</ixx>
            <iyy>0.000090623</iyy>
            <izz>0.000091036</izz>
            <ixy>0</ixy>
            <ixz>0</ixz>
            <iyz>0</iyz>
          </inertia>
        </inertial>
        <collision name="top_collision">
          <geometry>
            <sphere>
              <radius>0.001</radius>
            </sphere>
          </geometry>
        </collision>

        <visual name="top_visual">
          <geometry>
            <sphere>
              <radius>0.001</radius>
            </sphere>
          </geometry>
        </visual>
        <sensor type="ray" name="sensor">
          <pose>0 0 0 1.5707 0 0</pose>
          <visualize>true</visualize>
          <update_rate>30</update_rate>
          <ray>
            <scan>
              <horizontal>
                <samples>200</samples>
                <resolution>1</resolution>
                <min_angle>-0.78535</min_angle>
                <max_angle>0.78535</max_angle>
              </horizontal>
            </scan>
            <range>
              <min>0.05</min>
              <max>10</max>
              <resolution>0.02</resolution>
            </range>
          </ray>
        </sensor>
      </link>

      <joint type="ball" name="joint">
        <parent>base</parent>
        <child>top</child>
      </joint>
      <plugin name="RayPlugin" filename="libRayPlugin.so">
        <linkName>top</linkName>
      </plugin>
    </model>
</sdf>
